Traceback (most recent call last):
  File "C:\Users\denis.osses\Anaconda3\lib\site-packages\jupyter_cache\executors\utils.py", line 58, in single_nb_execution
    executenb(
  File "C:\Users\denis.osses\Anaconda3\lib\site-packages\nbclient\client.py", line 1204, in execute
    return NotebookClient(nb=nb, resources=resources, km=km, **kwargs).execute()
  File "C:\Users\denis.osses\Anaconda3\lib\site-packages\nbclient\util.py", line 84, in wrapped
    return just_run(coro(*args, **kwargs))
  File "C:\Users\denis.osses\Anaconda3\lib\site-packages\nbclient\util.py", line 62, in just_run
    return loop.run_until_complete(coro)
  File "C:\Users\denis.osses\Anaconda3\lib\asyncio\base_events.py", line 647, in run_until_complete
    return future.result()
  File "C:\Users\denis.osses\Anaconda3\lib\site-packages\nbclient\client.py", line 663, in async_execute
    await self.async_execute_cell(
  File "C:\Users\denis.osses\Anaconda3\lib\site-packages\nbclient\client.py", line 965, in async_execute_cell
    await self._check_raise_for_error(cell, cell_index, exec_reply)
  File "C:\Users\denis.osses\Anaconda3\lib\site-packages\nbclient\client.py", line 862, in _check_raise_for_error
    raise CellExecutionError.from_cell_and_msg(cell, exec_reply_content)
nbclient.exceptions.CellExecutionError: An error occurred while executing the following cell:
------------------
import numpy as np
import matplotlib.pyplot as plt

# Definimos la funci√≥n f(x, y)
def f(x, y):
    # Evitamos la divisi√≥n por cero para x = 0
    return np.divide(y-1, x, out=np.zeros_like(x), where=x!=0)

# Condiciones iniciales
x0 = 0
y0 = 1

# Intervalo de integraci√≥n
x = np.linspace(x0, 2, 100)

# Soluciones para diferentes valores de C
C_vals = [-1, 0, 1, 2]
sols = [1+C * x for C in C_vals]

# Visualizar las soluciones
for i, y_sol in enumerate(sols):
    plt.plot(x, y_sol, label=f'Soluci√≥n con C={C_values[i]}')

plt.xlabel('x')
plt.ylabel('y')
plt.title('Infinitas soluciones para una √∫nica condici√≥n inicial')
plt.axhline(1, color='black', linestyle='--', label='y(0) = 1')
plt.legend()
plt.grid(True)
plt.show()

------------------

[1;31m---------------------------------------------------------------------------[0m
[1;31mNameError[0m                                 Traceback (most recent call last)
[1;32m~\AppData\Local\Temp\ipykernel_13256\1591372535.py[0m in [0;36m<module>[1;34m[0m
[0;32m     20[0m [1;31m# Visualizar las soluciones[0m[1;33m[0m[1;33m[0m[0m
[0;32m     21[0m [1;32mfor[0m [0mi[0m[1;33m,[0m [0my_sol[0m [1;32min[0m [0menumerate[0m[1;33m([0m[0msols[0m[1;33m)[0m[1;33m:[0m[1;33m[0m[1;33m[0m[0m
[1;32m---> 22[1;33m     [0mplt[0m[1;33m.[0m[0mplot[0m[1;33m([0m[0mx[0m[1;33m,[0m [0my_sol[0m[1;33m,[0m [0mlabel[0m[1;33m=[0m[1;34mf'Soluci√≥n con C={C_values[i]}'[0m[1;33m)[0m[1;33m[0m[1;33m[0m[0m
[0m[0;32m     23[0m [1;33m[0m[0m
[0;32m     24[0m [0mplt[0m[1;33m.[0m[0mxlabel[0m[1;33m([0m[1;34m'x'[0m[1;33m)[0m[1;33m[0m[1;33m[0m[0m

[1;31mNameError[0m: name 'C_values' is not defined
NameError: name 'C_values' is not defined

